<?xml version="1.0"?>

<robot name="servo" xmlns:xacro="http://www.ros.org/wiki/xacro">

  <!-- Constants for robot dimensions -->
  <xacro:property name="PI" value="3.1415926535897931"/>
  <xacro:property name="mass" value="1" /> <!-- arbitrary value for mass -->
  <xacro:property name="mass1" value="5000" /> <!-- arbitrary value for mass -->
  <xacro:property name="radius" value="0.05" /> <!-- Radii of the cylinder-->
  <xacro:property name="length1" value="1.5" /> <!-- axel_holder -->
  <xacro:property name="length2" value="1" /> <!-- Rotator -->
  <xacro:property name="width" value="0.1" /> <!-- width of the beam -->
  <xacro:property name="offset" value="0" /> <!-- width of the beam -->

  <xacro:include filename="$(find servo_description)/urdf/servo.gazebo" />
  <xacro:include filename="$(find servo_description)/urdf/materials.xacro" />
  <!-- Used for fixing robot to Gazebo 'base_link' -->
<!--  <link name="world"/>

  <joint name="fixed" type="fixed">
    <parent link="world"/>
    <child link="axel_holder"/>
  </joint>

   Base Link -->
  <link name="axel_holder">
    <collision>
      <origin xyz="0.75 0 0.75" rpy="0 1.57 0"/>
      <geometry>
	       <box size="1.5 1.5 1.5"/>
      </geometry>
    </collision>

    <visual>
      <origin xyz="0.75 0 0.75" rpy="0 1.57 0"/>
      <geometry>
	       <box size="1.5 1.5 1.5"/>
      </geometry>
      <material name="orange"/>
    </visual>

    <inertial>
      <origin xyz="0.75 0 0.75" rpy="0 1.57 0"/>
      <mass value="5000"/>
      <inertia
	  ixx="1875" ixy="0.0" ixz="0.0"
	  iyy="1875" iyz="0.0"
	  izz="1875"/>
    </inertial>
  </link>

  <joint name="joint1" type="continuous">
    <parent link="axel_holder"/>
    <child link="rotater"/>
    <origin xyz="1.5 0 1.5" rpy="0 0 0"/>
    <axis xyz="1 0 0"/>
    <dynamics damping="0.7"/>
  </joint>


  <link name="rotater">
    <collision>
      <origin xyz="0.75 0 0.5" rpy="0 0 0"/>
      <geometry>
	       <box size="0.1 0.1 1"/>
      </geometry>
    </collision>

    <visual>
      <origin xyz="0.75 0 0.5" rpy="0 0 0"/>
      <geometry>
	       <box size="0.1 0.1 1"/>
      </geometry>
      <material name="black"/>
    </visual>

    <inertial>
      <origin xyz="0.75 0 0.5" rpy="0 0 0"/>
      <mass value="1"/>
      <inertia
	  ixx="0.00166" ixy="0.0" ixz="0.0"
	  iyy="0.08416" iyz="0.0"
	  izz="0.08416"/>
  </inertial>
  </link>

</robot>
